Workbook

Sheet 6.0.35
A1: 序号 | B1: 模板序号 | C1: 触发器序号 | D1: 模板名称 | E1: 触发器ID | F1: 英文名称 | G1: 中文名称 | H1: 原因
A2: 5 | B2: (3236/5) | D2: APC Smart-UPS 2200 RM by SNMP | E2: 18633 | F2: {#BATTERY_PACK}.{#CARTRIDGE_INDEX}: Battery has high temperature (over {$BATTERY.TEMP.MAX.WARN}℃ for {$TIME.PERIOD}) | G2: {#BATTERY_PACK}.{#CARTRIDGE_INDEX}: 电池温度太高(超过{$BATTERY.TEMP.MAX.WARN}℃持续{$TIME.PERIOD}) | H2: =IFERROR(IF(OR(MID(G2,FIND(":",G2)-1,1)="""",MID(G2,FIND(":",G2)-1,1)="}",MID(G2,FIND(":",G2)-1,1)=")",MID(G2,FIND(":",G2)-1,1)="]"),"",LEFT(F2,FIND(":",F2)-1)),"") | I2: =IFERROR(IF(OR(MID(G2,FIND(":",G2)-1,1)="""",MID(G2,FIND(":",G2)-1,1)="}",MID(G2,FIND(":",G2)-1,1)=")",MID(G2,FIND(":",G2)-1,1)="]"),"",RIGHT(G2,LEN(G2)-FIND(":",G2)-1)),"") | J2: =IF(AND(I2="",H2=""),G2,IF(H2="",I2,H2&": "&I2)) -> {#BATTERY_PACK}.{#CARTRIDGE_INDEX}: 电池温度太高(超过{$BATTERY.TEMP.MAX.WARN}℃持续{$TIME.PERIOD}) | K2: =IFERROR(IF(OR(MID(F2,FIND(":",F2)-1,1)="""",MID(F2,FIND(":",F2)-1,1)="}",MID(F2,FIND(":",F2)-1,1)=")",MID(F2,FIND(":",F2)-1,1)="]"),"",RIGHT(F2,LEN(F2)-FIND(":",F2)-1)),"") | L2: =LEN(F2)-LEN(SUBSTITUTE(F2,":","")) -> 1 | M2: =LEN(G2)-LEN(SUBSTITUTE(G2,":","")) -> 1 | N2: =LEN(G2)-LEN(SUBSTITUTE(G2,"：","")) -> 0 | O2: =IF(M2>=2,MID(G2,FIND(":",G2)+1,LEN(G2))) -> FALSE | P2: =INDEX(G:G,MATCH(G2,G:G,0)) -> {#BATTERY_PACK}.{#CARTRIDGE_INDEX}: 电池温度太高(超过{$BATTERY.TEMP.MAX.WARN}℃持续{$TIME.PERIOD}) | Q2: =IF(P2<>G2,"校验","") | R2: =INDEX('6.0.35'!I:I,MATCH(F2,'6.0.35'!K:K,0)) -> #N/A | S2: =INDEX('6.0.35'!J:J,MATCH(F2,'6.0.35'!F:F,0)) -> {#BATTERY_PACK}.{#CARTRIDGE_INDEX}: 电池温度太高(超过{$BATTERY.TEMP.MAX.WARN}℃持续{$TIME.PERIOD})
A3: 12 | B3: (3236/12) | D3: APC Smart-UPS 2200 RM by SNMP | E3: 18640 | F3: {#PHASEINDEX}: Unacceptable phase {#PHASEINDEX} input voltage (out of range {$UPS.INPUT_VOLT.MIN.WARN}-{$UPS.INPUT_VOLT.MAX.WARN}V for {$TIME.PERIOD}) | G3: {#PHASEINDEX}: 不可接受的相位{#PHASEINDEX}输入电压(超出范围{$UPS.INPUT_VOLT.MIN.WARN}-{$UPS.INPUT_VOLT.MAX.WARN}伏{$TIME.PERIOD})
A4: 13 | B4: (3236/13) | D4: APC Smart-UPS 2200 RM by SNMP | E4: 18641 | F4: {#PHASEINDEX}: Unacceptable phase {#PHASEINDEX} output voltage (out of range {$UPS.INPUT_VOLT.MIN.WARN}-{$UPS.INPUT_VOLT.MAX.WARN}V for {$TIME.PERIOD}) | G4: {#PHASEINDEX}: 不可接受的阶段{#PHASEINDEX}输出电压(超出范围{$UPS.INPUT_VOLT.MIN.WARN}-{$UPS.INPUT_VOLT.MAX.WARN}伏{$TIME.PERIOD})
A5: 16 | B5: (3236/16) | D5: APC Smart-UPS 3000 XLM by SNMP | E5: 18666 | F5: {#BATTERY_PACK}.{#CARTRIDGE_INDEX}: Battery has high temperature (over {$BATTERY.TEMP.MAX.WARN}℃ for {$TIME.PERIOD}) | G5: {#BATTERY_PACK}.{#CARTRIDGE_INDEX}: 电池温度太高(超过{$BATTERY.TEMP.MAX.WARN}℃持续{$TIME.PERIOD})
A6: 23 | B6: (3236/23) | D6: APC Smart-UPS 3000 XLM by SNMP | E6: 18673 | F6: {#PHASEINDEX}: Unacceptable phase {#PHASEINDEX} input voltage (out of range {$UPS.INPUT_VOLT.MIN.WARN}-{$UPS.INPUT_VOLT.MAX.WARN}V for {$TIME.PERIOD}) | G6: {#PHASEINDEX}: 不可接受的相位{#PHASEINDEX}输入电压(超出范围{$UPS.INPUT_VOLT.MIN.WARN}-{$UPS.INPUT_VOLT.MAX.WARN}伏{$TIME.PERIOD})
A7: 24 | B7: (3236/24) | D7: APC Smart-UPS 3000 XLM by SNMP | E7: 18674 | F7: {#PHASEINDEX}: Unacceptable phase {#PHASEINDEX} output voltage (out of range {$UPS.INPUT_VOLT.MIN.WARN}-{$UPS.INPUT_VOLT.MAX.WARN}V for {$TIME.PERIOD}) | G7: {#PHASEINDEX}: 不可接受的阶段{#PHASEINDEX}输出电压(超出范围{$UPS.INPUT_VOLT.MIN.WARN}-{$UPS.INPUT_VOLT.MAX.WARN}伏{$TIME.PERIOD})
A8: 27 | B8: (3236/27) | D8: APC Smart-UPS RT 1000 RM XL by SNMP | E8: 18699 | F8: {#BATTERY_PACK}.{#CARTRIDGE_INDEX}: Battery has high temperature (over {$BATTERY.TEMP.MAX.WARN}℃ for {$TIME.PERIOD}) | G8: {#BATTERY_PACK}.{#CARTRIDGE_INDEX}: 电池温度太高(超过{$BATTERY.TEMP.MAX.WARN}℃持续{$TIME.PERIOD})
A9: 34 | B9: (3236/34) | D9: APC Smart-UPS RT 1000 RM XL by SNMP | E9: 18706 | F9: {#PHASEINDEX}: Unacceptable phase {#PHASEINDEX} input voltage (out of range {$UPS.INPUT_VOLT.MIN.WARN}-{$UPS.INPUT_VOLT.MAX.WARN}V for {$TIME.PERIOD}) | G9: {#PHASEINDEX}: 不可接受的相位{#PHASEINDEX}输入电压(超出范围{$UPS.INPUT_VOLT.MIN.WARN}-{$UPS.INPUT_VOLT.MAX.WARN}伏{$TIME.PERIOD})
A10: 35 | B10: (3236/35) | D10: APC Smart-UPS RT 1000 RM XL by SNMP | E10: 18707 | F10: {#PHASEINDEX}: Unacceptable phase {#PHASEINDEX} output voltage (out of range {$UPS.INPUT_VOLT.MIN.WARN}-{$UPS.INPUT_VOLT.MAX.WARN}V for {$TIME.PERIOD}) | G10: {#PHASEINDEX}: 不可接受的阶段{#PHASEINDEX}输出电压(超出范围{$UPS.INPUT_VOLT.MIN.WARN}-{$UPS.INPUT_VOLT.MAX.WARN}伏{$TIME.PERIOD})
A11: 38 | B11: (3236/38) | D11: APC Smart-UPS RT 1000 XL by SNMP | E11: 18732 | F11: {#BATTERY_PACK}.{#CARTRIDGE_INDEX}: Battery has high temperature (over {$BATTERY.TEMP.MAX.WARN}℃ for {$TIME.PERIOD}) | G11: {#BATTERY_PACK}.{#CARTRIDGE_INDEX}: 电池温度太高(超过{$BATTERY.TEMP.MAX.WARN}℃持续{$TIME.PERIOD})
A12: 45 | B12: (3236/45) | D12: APC Smart-UPS RT 1000 XL by SNMP | E12: 18739 | F12: {#PHASEINDEX}: Unacceptable phase {#PHASEINDEX} input voltage (out of range {$UPS.INPUT_VOLT.MIN.WARN}-{$UPS.INPUT_VOLT.MAX.WARN}V for {$TIME.PERIOD}) | G12: {#PHASEINDEX}: 不可接受的相位{#PHASEINDEX}输入电压(超出范围{$UPS.INPUT_VOLT.MIN.WARN}-{$UPS.INPUT_VOLT.MAX.WARN}伏{$TIME.PERIOD})
A13: 46 | B13: (3236/46) | D13: APC Smart-UPS RT 1000 XL by SNMP | E13: 18740 | F13: {#PHASEINDEX}: Unacceptable phase {#PHASEINDEX} output voltage (out of range {$UPS.INPUT_VOLT.MIN.WARN}-{$UPS.INPUT_VOLT.MAX.WARN}V for {$TIME.PERIOD}) | G13: {#PHASEINDEX}: 不可接受的阶段{#PHASEINDEX}输出电压(超出范围{$UPS.INPUT_VOLT.MIN.WARN}-{$UPS.INPUT_VOLT.MAX.WARN}伏{$TIME.PERIOD})
A14: 49 | B14: (3236/49) | D14: APC Smart-UPS SRT 5000 by SNMP | E14: 18951 | F14: {#BATTERY_PACK}.{#CARTRIDGE_INDEX}: Battery has high temperature (over {$BATTERY.TEMP.MAX.WARN}℃ for {$TIME.PERIOD}) | G14: {#BATTERY_PACK}.{#CARTRIDGE_INDEX}: 电池温度太高(超过{$BATTERY.TEMP.MAX.WARN}℃持续{$TIME.PERIOD})
... A1699: 3233 | B1699: (3236/3233) | D1699: Zookeeper by HTTP | E1699: 17528 | F1699: Zookeeper: Too many pending syncs (over {$ZOOKEEPER.PENDING_SYNCS.MAX.WARN}% for 5 min) | G1699: Zookeeper: 挂起的同步太多(超过{$ZOOKEEPER.PENDING_SYNCS.MAX.WARN}%达5分钟)

Sheet 7.0.17
A1: 序号 | B1: 模板序号 | C1: 触发器序号 | D1: 模板名称 | E1: 触发器ID | F1: 英文名称 | G1: 中文名称 | H1: 原因
A2: 1 | B2: (3480/1) | D2: AIX by Zabbix agent | E2: 17115 | F2: AIX: FS [{#FSNAME}]: Running out of free inodes (free < {$VFS.FS.INODE.PFREE.MIN.WARN:"{#FSNAME}"}%) | G2: AIX: FS [{#FSNAME}]: 索引节点不足(空闲 < {$VFS.FS.INODE.PFREE.MIN.WARN: "{#FSNAME}"}%) | I2: =IFERROR(IF(OR(MID(G2,FIND(":",G2)-1,1)="""",MID(G2,FIND(":",G2)-1,1)="}",MID(G2,FIND(":",G2)-1,1)=")",MID(G2,FIND(":",G2)-1,1)="]"),"",RIGHT(G2,LEN(G2)-FIND(":",G2)-1)),"") -> FS [{#FSNAME}]: 索引节点不足(空闲 < {$VFS.FS.INODE.PFREE.MIN.WARN: "{#FSNAME}"}%) | J2: =IF(AND(I2="",H2=""),G2,IF(H2="",I2,H2&": "&I2)) -> FS [{#FSNAME}]: 索引节点不足(空闲 < {$VFS.FS.INODE.PFREE.MIN.WARN: "{#FSNAME}"}%) | K2: =IFERROR(IF(OR(MID(F2,FIND(":",F2)-1,1)="""",MID(F2,FIND(":",F2)-1,1)="}",MID(F2,FIND(":",F2)-1,1)=")",MID(F2,FIND(":",F2)-1,1)="]"),"",RIGHT(F2,LEN(F2)-FIND(":",F2)-1)),"") -> FS [{#FSNAME}]: Running out of free inodes (free < {$VFS.FS.INODE.PFREE.MIN.WARN:"{#FSNAME}"}%) | L2: =LEN(F2)-LEN(SUBSTITUTE(F2,":","")) -> 3 | M2: =LEN(G2)-LEN(SUBSTITUTE(G2,":","")) -> 3 | N2: =LEN(G2)-LEN(SUBSTITUTE(G2,"：","")) -> 0 | O2: =IF(M2>=2,MID(G2,FIND(":",G2)+1,LEN(G2))) -> FS [{#FSNAME}]: 索引节点不足(空闲 < {$VFS.FS.INODE.PFREE.MIN.WARN: "{#FSNAME}"}%) | P2: =INDEX(G:G,MATCH(G2,G:G,0)) -> AIX: FS [{#FSNAME}]: 索引节点不足(空闲 < {$VFS.FS.INODE.PFREE.MIN.WARN: "{#FSNAME}"}%) | Q2: =IF(P2<>G2,"校验","") | R2: =INDEX('6.0.35'!I:I,MATCH(F2,'6.0.35'!K:K,0)) -> #N/A | S2: =INDEX('6.0.35'!J:J,MATCH(F2,'6.0.35'!F:F,0)) -> #N/A
A3: 2 | B3: (3480/2) | D3: AIX by Zabbix agent | E3: 23682 | F3: AIX: {#FSNAME}: Running out of free inodes (free < {$VFS.FS.INODE.PFREE.MIN.CRIT:"{#FSNAME}"}%) | G3: AIX: {#FSNAME}: 可用inode耗尽(可用<{$VFS.FS.INODE.PFREE.MIN.CRIT: "{#FSNAME}"}%)
A4: 3 | B4: (3480/3) | D4: AIX by Zabbix agent | E4: 17114 | F4: AIX: FS [{#FSNAME}]: Space is low (used > {$VFS.FS.PUSED.MAX.WARN:"{#FSNAME}"}%, total {{?last(//vfs.fs.dependent.size[{#FSNAME},total])/1024/1024/1024}.fmtnum(1)}GB) | G4: AIX: FS [{#FSNAME}]: 空间不足(已用 > {$VFS.FS.PUSED.MAX.WARN: "{#FSNAME}"}%,总计 {{?last(//vfs.fs.dependent.size[{#FSNAME},total])/1024/1024/1024}.fmtnum(1)}GB)
A5: 4 | B5: (3480/4) | D5: AIX by Zabbix agent | E5: 23683 | F5: AIX: FS [{#FSNAME}]: Space is critically low (used > {$VFS.FS.PUSED.MAX.CRIT:"{#FSNAME}"}%, total {{?last(//vfs.fs.dependent.size[{#FSNAME},total])/1024/1024/1024}.fmtnum(1)}GB) | G5: AIX: FS [{#FSNAME}]: 空间严重不足(已用 > {$VFS.FS.PUSED.MAX.CRIT: "{#FSNAME}"}%,总计 {{?last(//vfs.fs.dependent.size[{#FSNAME},total])/1024/1024/1024}.fmtnum(1)}GB)
A6: 8 | B6: (3480/8) | D6: APC Smart-UPS 2200 RM by SNMP | E6: 18633 | F6: APC Smart-UPS: {#BATTERY_PACK}.{#CARTRIDGE_INDEX}: Battery has high temperature (over {$BATTERY.TEMP.MAX.WARN}℃ for {$TIME.PERIOD}) | G6: APC Smart-UPS: {#BATTERY_PACK}.{#CARTRIDGE_INDEX}: 电池温度太高(超过{$BATTERY.TEMP.MAX.WARN}℃持续{$TIME.PERIOD})
A7: 15 | B7: (3480/15) | D7: APC Smart-UPS 2200 RM by SNMP | E7: 18640 | F7: APC Smart-UPS: {#PHASEINDEX}: Unacceptable phase {#PHASEINDEX} input voltage (out of range {$UPS.INPUT_VOLT.MIN.WARN}-{$UPS.INPUT_VOLT.MAX.WARN}V for {$TIME.PERIOD}) | G7: APC Smart-UPS: {#PHASEINDEX}: 不可接受的相位{#PHASEINDEX}输入电压(超出范围{$UPS.INPUT_VOLT.MIN.WARN}-{$UPS.INPUT_VOLT.MAX.WARN}伏{$TIME.PERIOD})
A8: 16 | B8: (3480/16) | D8: APC Smart-UPS 2200 RM by SNMP | E8: 18641 | F8: APC Smart-UPS: {#PHASEINDEX}: Unacceptable phase {#PHASEINDEX} output voltage (out of range {$UPS.INPUT_VOLT.MIN.WARN}-{$UPS.INPUT_VOLT.MAX.WARN}V for {$TIME.PERIOD}) | G8: APC Smart-UPS: {#PHASEINDEX}: 不可接受的阶段{#PHASEINDEX}输出电压(超出范围{$UPS.INPUT_VOLT.MIN.WARN}-{$UPS.INPUT_VOLT.MAX.WARN}伏{$TIME.PERIOD})
A9: 19 | B9: (3480/19) | D9: APC Smart-UPS 3000 XLM by SNMP | E9: 18666 | F9: APC Smart-UPS: {#BATTERY_PACK}.{#CARTRIDGE_INDEX}: Battery has high temperature (over {$BATTERY.TEMP.MAX.WARN}℃ for {$TIME.PERIOD}) | G9: APC Smart-UPS: {#BATTERY_PACK}.{#CARTRIDGE_INDEX}: 电池温度太高(超过{$BATTERY.TEMP.MAX.WARN}℃持续{$TIME.PERIOD})
A10: 26 | B10: (3480/26) | D10: APC Smart-UPS 3000 XLM by SNMP | E10: 18673 | F10: APC Smart-UPS: {#PHASEINDEX}: Unacceptable phase {#PHASEINDEX} input voltage (out of range {$UPS.INPUT_VOLT.MIN.WARN}-{$UPS.INPUT_VOLT.MAX.WARN}V for {$TIME.PERIOD}) | G10: APC Smart-UPS: {#PHASEINDEX}: 不可接受的相位{#PHASEINDEX}输入电压(超出范围{$UPS.INPUT_VOLT.MIN.WARN}-{$UPS.INPUT_VOLT.MAX.WARN}伏{$TIME.PERIOD})
A11: 27 | B11: (3480/27) | D11: APC Smart-UPS 3000 XLM by SNMP | E11: 18674 | F11: APC Smart-UPS: {#PHASEINDEX}: Unacceptable phase {#PHASEINDEX} output voltage (out of range {$UPS.INPUT_VOLT.MIN.WARN}-{$UPS.INPUT_VOLT.MAX.WARN}V for {$TIME.PERIOD}) | G11: APC Smart-UPS: {#PHASEINDEX}: 不可接受的阶段{#PHASEINDEX}输出电压(超出范围{$UPS.INPUT_VOLT.MIN.WARN}-{$UPS.INPUT_VOLT.MAX.WARN}伏{$TIME.PERIOD})
A12: 30 | B12: (3480/30) | D12: APC Smart-UPS RT 1000 RM XL by SNMP | E12: 18699 | F12: APC Smart-UPS: {#BATTERY_PACK}.{#CARTRIDGE_INDEX}: Battery has high temperature (over {$BATTERY.TEMP.MAX.WARN}℃ for {$TIME.PERIOD}) | G12: APC Smart-UPS: {#BATTERY_PACK}.{#CARTRIDGE_INDEX}: 电池温度太高(超过{$BATTERY.TEMP.MAX.WARN}℃持续{$TIME.PERIOD})
A13: 37 | B13: (3480/37) | D13: APC Smart-UPS RT 1000 RM XL by SNMP | E13: 18706 | F13: APC Smart-UPS: {#PHASEINDEX}: Unacceptable phase {#PHASEINDEX} input voltage (out of range {$UPS.INPUT_VOLT.MIN.WARN}-{$UPS.INPUT_VOLT.MAX.WARN}V for {$TIME.PERIOD}) | G13: APC Smart-UPS: {#PHASEINDEX}: 不可接受的相位{#PHASEINDEX}输入电压(超出范围{$UPS.INPUT_VOLT.MIN.WARN}-{$UPS.INPUT_VOLT.MAX.WARN}伏{$TIME.PERIOD})
A14: 38 | B14: (3480/38) | D14: APC Smart-UPS RT 1000 RM XL by SNMP | E14: 18707 | F14: APC Smart-UPS: {#PHASEINDEX}: Unacceptable phase {#PHASEINDEX} output voltage (out of range {$UPS.INPUT_VOLT.MIN.WARN}-{$UPS.INPUT_VOLT.MAX.WARN}V for {$TIME.PERIOD}) | G14: APC Smart-UPS: {#PHASEINDEX}: 不可接受的阶段{#PHASEINDEX}输出电压(超出范围{$UPS.INPUT_VOLT.MIN.WARN}-{$UPS.INPUT_VOLT.MAX.WARN}伏{$TIME.PERIOD})
... A1735: 3480 | B1735: (3480/3480) | D1735: macOS by Zabbix agent | E1735: 23690 | F1735: macOS: FS [{#FSNAME}]: Space is critically low (used > {$VFS.FS.PUSED.MAX.CRIT:"{#FSNAME}"}%, total {{?last(//vfs.fs.dependent.size[{#FSNAME},total])/1024/1024/1024}.fmtnum(1)}GB) | G1735: macOS: FS [{#FSNAME}]: 空间严重不足(已用 > {$VFS.FS.PUSED.MAX.CRIT: "{#FSNAME}"}%,总计 {{?last(//vfs.fs.dependent.size[{#FSNAME},total])/1024/1024/1024}.fmtnum(1)}GB)

Sheet 整理
A1: 英文名称 | F1: 1 | P1: 2 | Z1: 3 | AJ1: 4 | AS1: 5 | BB1: 6 | BK1: 7
A2: AIX: FS [{#FSNAME}]: Running out of free inodes (free < {$VFS.FS.INODE.PFREE.MIN.WARN:"{#FSNAME}"}%) | B2: 运行的进程太多 | C2: =IFERROR(INDEX('6.0.35'!G:G,MATCH(A2,'6.0.35'!F:F,0)),IFERROR(INDEX('7.0.17'!G:G,MATCH(A2,'7.0.17'!F:F,0)),"")) -> AIX: FS [{#FSNAME}]: 索引节点不足(空闲 < {$VFS.FS.INODE.PFREE.MIN.WARN: "{#FSNAME}"}%) | D2: =IF(C2=B2,1,0) -> 0 | E2: =(LEN(A2)-LEN(SUBSTITUTE(A2,"{","")))/LEN("{") -> 3 | F2: =REPLACE(B2,H2,I2-H2+1,N2) -> #VALUE! | H2: =FIND("{",B2,1) -> #VALUE! | I2: =FIND("}",B2,H2+1) -> #VALUE! | J2: =MID(B2,H2,I2-H2+1) -> #VALUE! | L2: =FIND("{",A2,1) -> 10 | M2: =FIND("}",A2,L2+1) -> 18 | N2: =MID(A2,L2,M2-L2+1) -> {#FSNAME} | P2: =REPLACE($B2,R2,S2-R2+1,X2) -> #VALUE! | R2: =FIND("{",$B2,I2+1) -> #VALUE! | S2: =FIND("}",$B2,R2+1) -> #VALUE! | T2: =MID($B2,R2,S2-R2+1) -> #VALUE! | V2: =FIND("{",$A2,M2+1) -> 57 | W2: =FIND("}",$A2,V2+1) -> 96 | X2: =MID($A2,V2,W2-V2+1) -> {$VFS.FS.INODE.PFREE.MIN.WARN:"{#FSNAME} | Z2: =REPLACE($B2,AB2,AC2-AB2+1,AH2) -> #VALUE! | AB2: =FIND("{",$B2,S2+1) -> #VALUE! | AC2: =FIND("}",$B2,AB2+1) -> #VALUE! | AD2: =MID($B2,AB2,AC2-AB2+1) -> #VALUE! | AF2: =FIND("{",$A2,W2+1) -> #VALUE! | AG2: =FIND("}",$A2,AF2+1) -> #VALUE! | AH2: =MID($A2,AF2,AG2-AF2+1) -> #VALUE! | AJ2: =REPLACE($B2,AL2,AM2-AL2+1,AR2) -> #VALUE! | AL2: =FIND("{",$B2,AC2+1) -> #VALUE! | AM2: =FIND("}",$B2,AL2+1) -> #VALUE! | AN2: =MID($B2,AL2,AM2-AL2+1) -> #VALUE! | AP2: =FIND("{",$A2,AG2+1) -> #VALUE! | AQ2: =FIND("}",$A2,AP2+1) -> #VALUE! | AR2: =MID($A2,AP2,AQ2-AP2+1) -> #VALUE! | AS2: =REPLACE($B2,AU2,AV2-AU2+1,BA2) -> #VALUE! | AU2: =FIND("{",$B2,AM2+1) -> #VALUE! | AV2: =FIND("}",$B2,AU2+1) -> #VALUE! | AW2: =MID($B2,AU2,AV2-AU2+1) -> #VALUE! | AY2: =FIND("{",$A2,AQ2+1) -> #VALUE! | AZ2: =FIND("}",$A2,AY2+1) -> #VALUE! | BA2: =MID($A2,AY2,AZ2-AY2+1) -> #VALUE! | BB2: =REPLACE($B2,BD2,BE2-BD2+1,BJ2) -> #VALUE! | BD2: =FIND("{",$B2,AV2+1) -> #VALUE! | BE2: =FIND("}",$B2,BD2+1) -> #VALUE! | BF2: =MID($B2,BD2,BE2-BD2+1) -> #VALUE! | BH2: =FIND("{",$A2,AZ2+1) -> #VALUE! | BI2: =FIND("}",$A2,BH2+1) -> #VALUE! | BJ2: =MID($A2,BH2,BI2-BH2+1) -> #VALUE! | BK2: =REPLACE($B2,BM2,BN2-BM2+1,BS2) -> #VALUE! | BM2: =FIND("{",$B2,BE2+1) -> #VALUE! | BN2: =FIND("}",$B2,BM2+1) -> #VALUE! | BO2: =MID($B2,BM2,BN2-BM2+1) -> #VALUE! | BQ2: =FIND("{",$A2,BI2+1) -> #VALUE! | BR2: =FIND("}",$A2,BQ2+1) -> #VALUE! | BS2: =MID($A2,BQ2,BR2-BQ2+1) -> #VALUE!

Sheet 000
A1: 英文名称 | B1: AA | C1: AA | D1: AA | H1: AA
A2: AIX | B2: 戴尔R660：[{#DISK_NAME}]已更换（已收到新序列号） | C2: Running out of free inodes (free < {$VFS.FS.INODE.PFREE.MIN.WARN | D2: {#FSNAME}}%) | G2: =B2&":"&C2&":"&D2 -> 戴尔R660：[{#DISK_NAME}]已更换（已收到新序列号）: Running out of free inodes (free < {$VFS.FS.INODE.PFREE.MIN.WARN:{#FSNAME}}%) | H2: =INDEX('7.0.17'!G:G,MATCH(G2,'7.0.17'!F:F,0)) -> #N/A | I2: =A2&": "&H2 -> #N/A
A3: AIX | B3: 戴尔R660：[{#DISK_NAME}]已更换（已收到新序列号） | C3: Running out of free inodes (free < {$VFS.FS.INODE.PFREE.MIN.CRIT | D3: {#FSNAME}}%) | G3: =B3&":"&C3&":"&D3 -> 戴尔R660：[{#DISK_NAME}]已更换（已收到新序列号）: Running out of free inodes (free < {$VFS.FS.INODE.PFREE.MIN.CRIT:{#FSNAME}}%) | H3: =INDEX('7.0.17'!G:G,MATCH(G3,'7.0.17'!F:F,0)) -> #N/A | I3: =A3&": "&H3 -> #N/A
A4: AIX | B4: 戴尔R720：[{#DISK_NAME}]已更换（已收到新序列号） | C4: Space is low (used > {$VFS.FS.PUSED.MAX.WARN | D4: {#FSNAME}}%, total {{?last(//vfs.fs.dependent.size[{#FSNAME},total])/1024/1024/1024}.fmtnum(1)}GB) | G4: =B4&":"&C4&":"&D4 -> 戴尔R720：[{#DISK_NAME}]已更换（已收到新序列号）: Space is low (used > {$VFS.FS.PUSED.MAX.WARN:{#FSNAME}}%, total {{?last(//vfs.fs.dependent.size[{#FSNAME},total])/1024/1024/1024}.fmtnum(1)}GB) | H4: =INDEX('7.0.17'!G:G,MATCH(G4,'7.0.17'!F:F,0)) -> #N/A | I4: =A4&": "&H4 -> #N/A
A5: AIX | B5: 戴尔R720：[{#DISK_NAME}]已更换（已收到新序列号） | C5: Space is critically low (used > {$VFS.FS.PUSED.MAX.CRIT | D5: {#FSNAME}}%, total {{?last(//vfs.fs.dependent.size[{#FSNAME},total])/1024/1024/1024}.fmtnum(1)}GB) | G5: =B5&":"&C5&":"&D5 -> 戴尔R720：[{#DISK_NAME}]已更换（已收到新序列号）: Space is critically low (used > {$VFS.FS.PUSED.MAX.CRIT:{#FSNAME}}%, total {{?last(//vfs.fs.dependent.size[{#FSNAME},total])/1024/1024/1024}.fmtnum(1)}GB) | H5: =INDEX('7.0.17'!G:G,MATCH(G5,'7.0.17'!F:F,0)) -> #N/A | I5: =A5&": "&H5 -> #N/A
A6: APC Smart-UPS | B6: 戴尔R740：[{#DISK_NAME}]已更换（已收到新序列号） | C6: Battery has high temperature (over {$BATTERY.TEMP.MAX.WARN}℃ for {$TIME.PERIOD}) | G6: =B6&":"&C6 -> 戴尔R740：[{#DISK_NAME}]已更换（已收到新序列号）: Battery has high temperature (over {$BATTERY.TEMP.MAX.WARN}℃ for {$TIME.PERIOD}) | H6: =INDEX('7.0.17'!G:G,MATCH(G6,'7.0.17'!F:F,0)) -> #N/A | I6: =A6&": "&H6 -> #N/A
A7: APC Smart-UPS | B7: 戴尔R740：[{#DISK_NAME}]已更换（已收到新序列号） | C7: Unacceptable phase {#PHASEINDEX} input voltage (out of range {$UPS.INPUT_VOLT.MIN.WARN}-{$UPS.INPUT_VOLT.MAX.WARN}V for {$TIME.PERIOD}) | G7: =B7&":"&C7 -> 戴尔R740：[{#DISK_NAME}]已更换（已收到新序列号）: Unacceptable phase {#PHASEINDEX} input voltage (out of range {$UPS.INPUT_VOLT.MIN.WARN}-{$UPS.INPUT_VOLT.MAX.WARN}V for {$TIME.PERIOD}) | H7: =INDEX('7.0.17'!G:G,MATCH(G7,'7.0.17'!F:F,0)) -> #N/A | I7: =A7&": "&H7 -> #N/A
A8: APC Smart-UPS | B8: 戴尔R750：[{#DISK_NAME}]已更换（已收到新序列号） | C8: Unacceptable phase {#PHASEINDEX} output voltage (out of range {$UPS.INPUT_VOLT.MIN.WARN}-{$UPS.INPUT_VOLT.MAX.WARN}V for {$TIME.PERIOD}) | G8: =B8&":"&C8 -> 戴尔R750：[{#DISK_NAME}]已更换（已收到新序列号）: Unacceptable phase {#PHASEINDEX} output voltage (out of range {$UPS.INPUT_VOLT.MIN.WARN}-{$UPS.INPUT_VOLT.MAX.WARN}V for {$TIME.PERIOD}) | H8: =INDEX('7.0.17'!G:G,MATCH(G8,'7.0.17'!F:F,0)) -> #N/A | I8: =A8&": "&H8 -> #N/A
A9: APC Smart-UPS | B9: 戴尔R750：[{#DISK_NAME}]已更换（已收到新序列号） | C9: Battery has high temperature (over {$BATTERY.TEMP.MAX.WARN}℃ for {$TIME.PERIOD}) | G9: =B9&":"&C9 -> 戴尔R750：[{#DISK_NAME}]已更换（已收到新序列号）: Battery has high temperature (over {$BATTERY.TEMP.MAX.WARN}℃ for {$TIME.PERIOD}) | H9: =INDEX('7.0.17'!G:G,MATCH(G9,'7.0.17'!F:F,0)) -> #N/A | I9: =A9&": "&H9 -> #N/A
A10: APC Smart-UPS | B10: 戴尔R820：[{#DISK_NAME}]已更换（已收到新序列号） | C10: Unacceptable phase {#PHASEINDEX} input voltage (out of range {$UPS.INPUT_VOLT.MIN.WARN}-{$UPS.INPUT_VOLT.MAX.WARN}V for {$TIME.PERIOD}) | G10: =B10&":"&C10 -> 戴尔R820：[{#DISK_NAME}]已更换（已收到新序列号）: Unacceptable phase {#PHASEINDEX} input voltage (out of range {$UPS.INPUT_VOLT.MIN.WARN}-{$UPS.INPUT_VOLT.MAX.WARN}V for {$TIME.PERIOD}) | H10: =INDEX('7.0.17'!G:G,MATCH(G10,'7.0.17'!F:F,0)) -> #N/A | I10: =A10&": "&H10 -> #N/A
A11: APC Smart-UPS | B11: 戴尔R820：[{#DISK_NAME}]已更换（已收到新序列号） | C11: Unacceptable phase {#PHASEINDEX} output voltage (out of range {$UPS.INPUT_VOLT.MIN.WARN}-{$UPS.INPUT_VOLT.MAX.WARN}V for {$TIME.PERIOD}) | G11: =B11&":"&C11 -> 戴尔R820：[{#DISK_NAME}]已更换（已收到新序列号）: Unacceptable phase {#PHASEINDEX} output voltage (out of range {$UPS.INPUT_VOLT.MIN.WARN}-{$UPS.INPUT_VOLT.MAX.WARN}V for {$TIME.PERIOD}) | H11: =INDEX('7.0.17'!G:G,MATCH(G11,'7.0.17'!F:F,0)) -> #N/A | I11: =A11&": "&H11 -> #N/A
A12: APC Smart-UPS | B12: 戴尔R840：[{#DISK_NAME}]已更换（已收到新序列号） | C12: Battery has high temperature (over {$BATTERY.TEMP.MAX.WARN}℃ for {$TIME.PERIOD}) | G12: =B12&":"&C12 -> 戴尔R840：[{#DISK_NAME}]已更换（已收到新序列号）: Battery has high temperature (over {$BATTERY.TEMP.MAX.WARN}℃ for {$TIME.PERIOD}) | H12: =INDEX('7.0.17'!G:G,MATCH(G12,'7.0.17'!F:F,0)) -> #N/A | I12: =A12&": "&H12 -> #N/A
A13: APC Smart-UPS | B13: 戴尔R840：[{#DISK_NAME}]已更换（已收到新序列号） | C13: Unacceptable phase {#PHASEINDEX} input voltage (out of range {$UPS.INPUT_VOLT.MIN.WARN}-{$UPS.INPUT_VOLT.MAX.WARN}V for {$TIME.PERIOD}) | G13: =B13&":"&C13 -> 戴尔R840：[{#DISK_NAME}]已更换（已收到新序列号）: Unacceptable phase {#PHASEINDEX} input voltage (out of range {$UPS.INPUT_VOLT.MIN.WARN}-{$UPS.INPUT_VOLT.MAX.WARN}V for {$TIME.PERIOD}) | H13: =INDEX('7.0.17'!G:G,MATCH(G13,'7.0.17'!F:F,0)) -> #N/A | I13: =A13&": "&H13 -> #N/A
A14: APC Smart-UPS | B14: 戴尔远程管理控制器（iDRAC）：[{#DISK_NAME}]已更换（已收到新序列号） | C14: Unacceptable phase {#PHASEINDEX} output voltage (out of range {$UPS.INPUT_VOLT.MIN.WARN}-{$UPS.INPUT_VOLT.MAX.WARN}V for {$TIME.PERIOD}) | G14: =B14&":"&C14 -> 戴尔远程管理控制器（iDRAC）：[{#DISK_NAME}]已更换（已收到新序列号）: Unacceptable phase {#PHASEINDEX} output voltage (out of range {$UPS.INPUT_VOLT.MIN.WARN}-{$UPS.INPUT_VOLT.MAX.WARN}V for {$TIME.PERIOD}) | H14: =INDEX('7.0.17'!G:G,MATCH(G14,'7.0.17'!F:F,0)) -> #N/A | I14: =A14&": "&H14 -> #N/A
A15: APC Smart-UPS | B15: PA-440：设备证书：即将过期（距离过期时间少于{$PAN.PA440.CERT.DEVICE.EXPIRY.WARN} ） | C15: Battery has high temperature (over {$BATTERY.TEMP.MAX.WARN}℃ for {$TIME.PERIOD}) | G15: =B15&":"&C15 -> PA-440：设备证书：即将过期（距离过期时间少于{$PAN.PA440.CERT.DEVICE.EXPIRY.WARN} ）: Battery has high temperature (over {$BATTERY.TEMP.MAX.WARN}℃ for {$TIME.PERIOD}) | H15: =INDEX('7.0.17'!G:G,MATCH(G15,'7.0.17'!F:F,0)) -> #N/A | I15: =A15&": "&H15 -> #N/A
A16: APC Smart-UPS | B16: PA-440：证书[{#CERTNAME}]：即将过期（距离过期时间少于{$PAN.PA440.CERT.EXPIRY.WARN} ） | C16: Unacceptable phase {#PHASEINDEX} input voltage (out of range {$UPS.INPUT_VOLT.MIN.WARN}-{$UPS.INPUT_VOLT.MAX.WARN}V for {$TIME.PERIOD}) | G16: =B16&":"&C16 -> PA-440：证书[{#CERTNAME}]：即将过期（距离过期时间少于{$PAN.PA440.CERT.EXPIRY.WARN} ）: Unacceptable phase {#PHASEINDEX} input voltage (out of range {$UPS.INPUT_VOLT.MIN.WARN}-{$UPS.INPUT_VOLT.MAX.WARN}V for {$TIME.PERIOD}) | H16: =INDEX('7.0.17'!G:G,MATCH(G16,'7.0.17'!F:F,0)) -> #N/A | I16: =A16&": "&H16 -> #N/A
A17: APC Smart-UPS | B17: PA-440：高可用性（HA）状态已更改为“{ITEM.VALUE}” | C17: Unacceptable phase {#PHASEINDEX} output voltage (out of range {$UPS.INPUT_VOLT.MIN.WARN}-{$UPS.INPUT_VOLT.MAX.WARN}V for {$TIME.PERIOD}) | G17: =B17&":"&C17 -> PA-440：高可用性（HA）状态已更改为“{ITEM.VALUE}”: Unacceptable phase {#PHASEINDEX} output voltage (out of range {$UPS.INPUT_VOLT.MIN.WARN}-{$UPS.INPUT_VOLT.MAX.WARN}V for {$TIME.PERIOD}) | H17: =INDEX('7.0.17'!G:G,MATCH(G17,'7.0.17'!F:F,0)) -> #N/A | I17: =A17&": "&H17 -> #N/A
... A38: APC UPS | B38: {#PHASEINDEX} | C38: Unacceptable phase {#PHASEINDEX} output voltage (out of range {$UPS.INPUT_VOLT.MIN.WARN}-{$UPS.INPUT_VOLT.MAX.WARN}V for {$TIME.PERIOD}) | G38: =B38&":"&C38 -> {#PHASEINDEX}: Unacceptable phase {#PHASEINDEX} output voltage (out of range {$UPS.INPUT_VOLT.MIN.WARN}-{$UPS.INPUT_VOLT.MAX.WARN}V for {$TIME.PERIOD}) | H38: =INDEX('7.0.17'!G:G,MATCH(G38,'7.0.17'!F:F,0)) -> #N/A | I38: =A38&": "&H38 -> #N/A
A39: AWS EC2 | B39: Burst balance is too low (less {$AWS.EBS.BURST.CREDIT.BALANCE.MIN.WARN}% for 5m) | G39: =B39 -> Burst balance is too low (less {$AWS.EBS.BURST.CREDIT.BALANCE.MIN.WARN}% for 5m) | H39: =INDEX('7.0.17'!G:G,MATCH(G39,'7.0.17'!F:F,0)) -> #N/A | I39: =A39&": "&H39 -> #N/A
A40: AWS ECS Cluster | B40: [{#AWS.ECS.SERVICE.NAME}] | C40: High CPU utilization (over {$AWS.ECS.CLUSTER.SERVICE.CPU.UTIL.WARN}% for 15m) | G40: =B40&":"&C40 -> [{#AWS.ECS.SERVICE.NAME}]: High CPU utilization (over {$AWS.ECS.CLUSTER.SERVICE.CPU.UTIL.WARN}% for 15m) | H40: =INDEX('7.0.17'!G:G,MATCH(G40,'7.0.17'!F:F,0)) -> #N/A | I40: =A40&": "&H40 -> #N/A
A41: AWS ECS Cluster | B41: [{#AWS.ECS.SERVICE.NAME}] | C41: High memory utilization (over {$AWS.ECS.CLUSTER.SERVICE.MEMORY.UTIL.WARN}% for 15m) | G41: =B41&":"&C41 -> [{#AWS.ECS.SERVICE.NAME}]: High memory utilization (over {$AWS.ECS.CLUSTER.SERVICE.MEMORY.UTIL.WARN}% for 15m) | H41: =INDEX('7.0.17'!G:G,MATCH(G41,'7.0.17'!F:F,0)) -> #N/A | I41: =A41&": "&H41 -> #N/A
A42: AWS ECS Serverless | B42: [{#AWS.ECS.SERVICE.NAME}] | C42: High CPU utilization (over {$AWS.ECS.CLUSTER.SERVICE.CPU.UTIL.WARN}% for 15m) | G42: =B42&":"&C42 -> [{#AWS.ECS.SERVICE.NAME}]: High CPU utilization (over {$AWS.ECS.CLUSTER.SERVICE.CPU.UTIL.WARN}% for 15m) | H42: =INDEX('7.0.17'!G:G,MATCH(G42,'7.0.17'!F:F,0)) -> #N/A | I42: =A42&": "&H42 -> #N/A
A43: AWS ECS Serverless | B43: [{#AWS.ECS.SERVICE.NAME}] | C43: High memory utilization (over {$AWS.ECS.CLUSTER.SERVICE.MEMORY.UTIL.WARN}% for 15m) | G43: =B43&":"&C43 -> [{#AWS.ECS.SERVICE.NAME}]: High memory utilization (over {$AWS.ECS.CLUSTER.SERVICE.MEMORY.UTIL.WARN}% for 15m) | H43: =INDEX('7.0.17'!G:G,MATCH(G43,'7.0.17'!F:F,0)) -> #N/A | I43: =A43&": "&H43 -> #N/A
A44: AWS ELB ALB | B44: [{#ALARM_NAME}] has 'Alarm' state (reason | C44: {ITEM.LASTVALUE2}) | G44: =B44&":"&C44 -> [{#ALARM_NAME}] has 'Alarm' state (reason: {ITEM.LASTVALUE2}) | H44: =INDEX('7.0.17'!G:G,MATCH(G44,'7.0.17'!F:F,0)) -> #N/A | I44: =A44&": "&H44 -> #N/A
A45: AWS ELB ALB | B45: [{#ALARM_NAME}] has 'Insufficient data' state | G45: =B45 -> [{#ALARM_NAME}] has 'Insufficient data' state | H45: =INDEX('7.0.17'!G:G,MATCH(G45,'7.0.17'!F:F,0)) -> #N/A | I45: =A45&": "&H45 -> #N/A
A46: AWS ELB NLB | B46: [{#ALARM_NAME}] has 'Alarm' state (reason | C46: {ITEM.LASTVALUE2}) | G46: =B46&":"&C46 -> [{#ALARM_NAME}] has 'Alarm' state (reason: {ITEM.LASTVALUE2}) | H46: =INDEX('7.0.17'!G:G,MATCH(G46,'7.0.17'!F:F,0)) -> #N/A | I46: =A46&": "&H46 -> #N/A
A47: AWS ELB NLB | B47: [{#ALARM_NAME}] has 'Insufficient data' state | G47: =B47 -> [{#ALARM_NAME}] has 'Insufficient data' state | H47: =INDEX('7.0.17'!G:G,MATCH(G47,'7.0.17'!F:F,0)) -> #N/A | I47: =A47&": "&H47 -> #N/A
A48: AWS ELB NLB | B48: [{#AWS.ELB.TARGET.GROUP.NAME}] | C48: Healthy Host Count = 0 | G48: =B48&":"&C48 -> [{#AWS.ELB.TARGET.GROUP.NAME}]: Healthy Host Count = 0 | H48: =INDEX('7.0.17'!G:G,MATCH(G48,'7.0.17'!F:F,0)) -> #N/A | I48: =A48&": "&H48 -> #N/A
A49: AWS ELB NLB | B49: [{#AWS.ELB.TARGET.GROUP.NAME}] | C49: Unhealthy Host Count > {$AWS.ELB.UNHEALTHY.HOST.MAX} | G49: =B49&":"&C49 -> [{#AWS.ELB.TARGET.GROUP.NAME}]: Unhealthy Host Count > {$AWS.ELB.UNHEALTHY.HOST.MAX} | H49: =INDEX('7.0.17'!G:G,MATCH(G49,'7.0.17'!F:F,0)) -> #N/A | I49: =A49&": "&H49 -> #N/A
A50: AWS Lambda | B50: [{#ALARM_NAME}] has 'Alarm' state (reason | C50: {ITEM.LASTVALUE2}) | G50: =B50&":"&C50 -> [{#ALARM_NAME}] has 'Alarm' state (reason: {ITEM.LASTVALUE2}) | H50: =INDEX('7.0.17'!G:G,MATCH(G50,'7.0.17'!F:F,0)) -> #N/A | I50: =A50&": "&H50 -> #N/A
A51: AWS Lambda | B51: [{#ALARM_NAME}] has 'Insufficient data' state | G51: =B51 -> [{#ALARM_NAME}] has 'Insufficient data' state | H51: =INDEX('7.0.17'!G:G,MATCH(G51,'7.0.17'!F:F,0)) -> #N/A | I51: =A51&": "&H51 -> #N/A
A52: Acronis | B52: Alert [{#ALERT_ID}] | C52: "critical" severity | G52: =B52&":"&C52 -> Alert [{#ALERT_ID}]: "critical" severity | H52: =INDEX('7.0.17'!G:G,MATCH(G52,'7.0.17'!F:F,0)) -> #N/A | I52: =A52&": "&H52 -> #N/A
A53: Acronis | B53: Alert [{#ALERT_ID}] | C53: "error" severity | G53: =B53&":"&C53 -> Alert [{#ALERT_ID}]: "error" severity | H53: =INDEX('7.0.17'!G:G,MATCH(G53,'7.0.17'!F:F,0)) -> #N/A | I53: =A53&": "&H53 -> #N/A
A54: Acronis | B54: Alert [{#ALERT_ID}] | C54: "warning" severity | G54: =B54&":"&C54 -> Alert [{#ALERT_ID}]: "warning" severity | H54: =INDEX('7.0.17'!G:G,MATCH(G54,'7.0.17'!F:F,0)) -> #N/A | I54: =A54&": "&H54 -> #N/A
A55: Alcatel TiMOS | B55: Interface {#IFNAME}({#IFALIAS}) | C55: High error rate (>{$IF.ERRORS.WARN | D55: {#IFNAME}} for 5m) | G55: =B55&":"&C55&":"&D55 -> Interface {#IFNAME}({#IFALIAS}): High error rate (>{$IF.ERRORS.WARN:{#IFNAME}} for 5m) | H55: =INDEX('7.0.17'!G:G,MATCH(G55,'7.0.17'!F:F,0)) -> #N/A | I55: =A55&": "&H55 -> #N/A
A56: Alcatel TiMOS | B56: Interface {#IFNAME}({#IFALIAS}) | C56: High bandwidth usage (>{$IF.UTIL.MAX | D56: {#IFNAME}}%) | G56: =B56&":"&C56&":"&D56 -> Interface {#IFNAME}({#IFALIAS}): High bandwidth usage (>{$IF.UTIL.MAX:{#IFNAME}}%) | H56: =INDEX('7.0.17'!G:G,MATCH(G56,'7.0.17'!F:F,0)) -> #N/A | I56: =A56&": "&H56 -> #N/A
A57: Alcatel TiMOS | B57: {#SNMPVALUE} | C57: Temperature is above critical threshold | D57: >{$TEMP_CRIT | E57: {#SNMPVALUE}} | G57: =B57&":"&C57&":"&D57&":"&E57 -> {#SNMPVALUE}: Temperature is above critical threshold: >{$TEMP_CRIT:{#SNMPVALUE}} | H57: =INDEX('7.0.17'!G:G,MATCH(G57,'7.0.17'!F:F,0)) -> #N/A | I57: =A57&": "&H57 -> #N/A
A58: Alcatel TiMOS | B58: {#SNMPVALUE} | C58: Temperature is above warning threshold | D58: >{$TEMP_WARN | E58: {#SNMPVALUE}} | G58: =B58&":"&C58&":"&D58&":"&E58 -> {#SNMPVALUE}: Temperature is above warning threshold: >{$TEMP_WARN:{#SNMPVALUE}} | H58: =INDEX('7.0.17'!G:G,MATCH(G58,'7.0.17'!F:F,0)) -> #N/A | I58: =A58&": "&H58 -> #N/A
A59: Alcatel TiMOS | B59: {#SNMPVALUE} | C59: Temperature is too low | D59: <{$TEMP_CRIT_LOW | E59: {#SNMPVALUE}} | G59: =B59&":"&C59&":"&D59&":"&E59 -> {#SNMPVALUE}: Temperature is too low: <{$TEMP_CRIT_LOW:{#SNMPVALUE}} | H59: =INDEX('7.0.17'!G:G,MATCH(G59,'7.0.17'!F:F,0)) -> #N/A | I59: =A59&": "&H59 -> #N/A
A60: Alcatel TiMOS | B60: {#ENT_NAME} | C60: Device has been replaced (new serial number received) | G60: =B60&":"&C60 -> {#ENT_NAME}: Device has been replaced (new serial number received) | H60: =INDEX('7.0.17'!G:G,MATCH(G60,'7.0.17'!F:F,0)) -> #N/A | I60: =A60&": "&H60 -> #N/A
...

Sheet 6.4.14
A1: 序号 | B1: 模板序号 | C1: 触发器序号 | D1: 模板名称 | E1: 触发器ID | F1: 英文名称 | G1: 中文名称 | H1: 原因
A2: 6 | B2: (310/2) | C2: (11/3) | D2: APC Smart-UPS 2200 RM by SNMP | E2: 18633 | F2: {#BATTERY_PACK}.{#CARTRIDGE_INDEX}: Battery has high temperature (over {$BATTERY.TEMP.MAX.WARN}℃ for {$TIME.PERIOD}) | G2: {#BATTERY_PACK}.{#CARTRIDGE_INDEX}: 电池温度太高(超过{$BATTERY.TEMP.MAX.WARN}℃持续{$TIME.PERIOD}) | H2: =IFERROR(IF(OR(MID(G2,FIND(":",G2)-1,1)="""",MID(G2,FIND(":",G2)-1,1)="}",MID(G2,FIND(":",G2)-1,1)=")",MID(G2,FIND(":",G2)-1,1)="]"),"",LEFT(F2,FIND(":",F2)-1)),"") | I2: =IFERROR(IF(OR(MID(G2,FIND(":",G2)-1,1)="""",MID(G2,FIND(":",G2)-1,1)="}",MID(G2,FIND(":",G2)-1,1)=")",MID(G2,FIND(":",G2)-1,1)="]"),"",RIGHT(G2,LEN(G2)-FIND(":",G2)-1)),"") | J2: =IF(AND(I2="",H2=""),G2,H2&": "&I2) -> {#BATTERY_PACK}.{#CARTRIDGE_INDEX}: 电池温度太高(超过{$BATTERY.TEMP.MAX.WARN}℃持续{$TIME.PERIOD}) | K2: =IFERROR(IF(OR(MID(F2,FIND(":",F2)-1,1)="""",MID(F2,FIND(":",F2)-1,1)="}",MID(F2,FIND(":",F2)-1,1)=")",MID(F2,FIND(":",F2)-1,1)="]"),"",RIGHT(F2,LEN(F2)-FIND(":",F2)-1)),"")
A3: 13 | B3: (310/2) | C3: (11/10) | D3: APC Smart-UPS 2200 RM by SNMP | E3: 18640 | F3: {#PHASEINDEX}: Unacceptable phase {#PHASEINDEX} input voltage (out of range {$UPS.INPUT_VOLT.MIN.WARN}-{$UPS.INPUT_VOLT.MAX.WARN}V for {$TIME.PERIOD}) | G3: {#PHASEINDEX}: 不可接受的相位{#PHASEINDEX}输入电压(超出范围{$UPS.INPUT_VOLT.MIN.WARN}-{$UPS.INPUT_VOLT.MAX.WARN}伏{$TIME.PERIOD}) | H3: =IFERROR(IF(OR(MID(G3,FIND(":",G3)-1,1)="""",MID(G3,FIND(":",G3)-1,1)="}",MID(G3,FIND(":",G3)-1,1)=")",MID(G3,FIND(":",G3)-1,1)="]"),"",LEFT(F3,FIND(":",F3)-1)),"") | I3: =IFERROR(IF(OR(MID(G3,FIND(":",G3)-1,1)="""",MID(G3,FIND(":",G3)-1,1)="}",MID(G3,FIND(":",G3)-1,1)=")",MID(G3,FIND(":",G3)-1,1)="]"),"",RIGHT(G3,LEN(G3)-FIND(":",G3)-1)),"") | J3: =IF(AND(I3="",H3=""),G3,H3&": "&I3) -> {#PHASEINDEX}: 不可接受的相位{#PHASEINDEX}输入电压(超出范围{$UPS.INPUT_VOLT.MIN.WARN}-{$UPS.INPUT_VOLT.MAX.WARN}伏{$TIME.PERIOD}) | K3: =IFERROR(IF(OR(MID(F3,FIND(":",F3)-1,1)="""",MID(F3,FIND(":",F3)-1,1)="}",MID(F3,FIND(":",F3)-1,1)=")",MID(F3,FIND(":",F3)-1,1)="]"),"",RIGHT(F3,LEN(F3)-FIND(":",F3)-1)),"")
A4: 14 | B4: (310/2) | C4: (11/11) | D4: APC Smart-UPS 2200 RM by SNMP | E4: 18641 | F4: {#PHASEINDEX}: Unacceptable phase {#PHASEINDEX} output voltage (out of range {$UPS.INPUT_VOLT.MIN.WARN}-{$UPS.INPUT_VOLT.MAX.WARN}V for {$TIME.PERIOD}) | G4: {#PHASEINDEX}: 不可接受的阶段{#PHASEINDEX}输出电压(超出范围{$UPS.INPUT_VOLT.MIN.WARN}-{$UPS.INPUT_VOLT.MAX.WARN}伏{$TIME.PERIOD}) | H4: =IFERROR(IF(OR(MID(G4,FIND(":",G4)-1,1)="""",MID(G4,FIND(":",G4)-1,1)="}",MID(G4,FIND(":",G4)-1,1)=")",MID(G4,FIND(":",G4)-1,1)="]"),"",LEFT(F4,FIND(":",F4)-1)),"") | I4: =IFERROR(IF(OR(MID(G4,FIND(":",G4)-1,1)="""",MID(G4,FIND(":",G4)-1,1)="}",MID(G4,FIND(":",G4)-1,1)=")",MID(G4,FIND(":",G4)-1,1)="]"),"",RIGHT(G4,LEN(G4)-FIND(":",G4)-1)),"") | J4: =IF(AND(I4="",H4=""),G4,H4&": "&I4) -> {#PHASEINDEX}: 不可接受的阶段{#PHASEINDEX}输出电压(超出范围{$UPS.INPUT_VOLT.MIN.WARN}-{$UPS.INPUT_VOLT.MAX.WARN}伏{$TIME.PERIOD}) | K4: =IFERROR(IF(OR(MID(F4,FIND(":",F4)-1,1)="""",MID(F4,FIND(":",F4)-1,1)="}",MID(F4,FIND(":",F4)-1,1)=")",MID(F4,FIND(":",F4)-1,1)="]"),"",RIGHT(F4,LEN(F4)-FIND(":",F4)-1)),"")
A5: 17 | B5: (310/3) | C5: (11/3) | D5: APC Smart-UPS 3000 XLM by SNMP | E5: 18666 | F5: {#BATTERY_PACK}.{#CARTRIDGE_INDEX}: Battery has high temperature (over {$BATTERY.TEMP.MAX.WARN}℃ for {$TIME.PERIOD}) | G5: {#BATTERY_PACK}.{#CARTRIDGE_INDEX}: 电池温度太高(超过{$BATTERY.TEMP.MAX.WARN}℃持续{$TIME.PERIOD}) | H5: =IFERROR(IF(OR(MID(G5,FIND(":",G5)-1,1)="""",MID(G5,FIND(":",G5)-1,1)="}",MID(G5,FIND(":",G5)-1,1)=")",MID(G5,FIND(":",G5)-1,1)="]"),"",LEFT(F5,FIND(":",F5)-1)),"") | I5: =IFERROR(IF(OR(MID(G5,FIND(":",G5)-1,1)="""",MID(G5,FIND(":",G5)-1,1)="}",MID(G5,FIND(":",G5)-1,1)=")",MID(G5,FIND(":",G5)-1,1)="]"),"",RIGHT(G5,LEN(G5)-FIND(":",G5)-1)),"") | J5: =IF(AND(I5="",H5=""),G5,H5&": "&I5) -> {#BATTERY_PACK}.{#CARTRIDGE_INDEX}: 电池温度太高(超过{$BATTERY.TEMP.MAX.WARN}℃持续{$TIME.PERIOD}) | K5: =IFERROR(IF(OR(MID(F5,FIND(":",F5)-1,1)="""",MID(F5,FIND(":",F5)-1,1)="}",MID(F5,FIND(":",F5)-1,1)=")",MID(F5,FIND(":",F5)-1,1)="]"),"",RIGHT(F5,LEN(F5)-FIND(":",F5)-1)),"")
A6: 24 | B6: (310/3) | C6: (11/10) | D6: APC Smart-UPS 3000 XLM by SNMP | E6: 18673 | F6: {#PHASEINDEX}: Unacceptable phase {#PHASEINDEX} input voltage (out of range {$UPS.INPUT_VOLT.MIN.WARN}-{$UPS.INPUT_VOLT.MAX.WARN}V for {$TIME.PERIOD}) | G6: {#PHASEINDEX}: 不可接受的相位{#PHASEINDEX}输入电压(超出范围{$UPS.INPUT_VOLT.MIN.WARN}-{$UPS.INPUT_VOLT.MAX.WARN}伏{$TIME.PERIOD}) | H6: =IFERROR(IF(OR(MID(G6,FIND(":",G6)-1,1)="""",MID(G6,FIND(":",G6)-1,1)="}",MID(G6,FIND(":",G6)-1,1)=")",MID(G6,FIND(":",G6)-1,1)="]"),"",LEFT(F6,FIND(":",F6)-1)),"") | I6: =IFERROR(IF(OR(MID(G6,FIND(":",G6)-1,1)="""",MID(G6,FIND(":",G6)-1,1)="}",MID(G6,FIND(":",G6)-1,1)=")",MID(G6,FIND(":",G6)-1,1)="]"),"",RIGHT(G6,LEN(G6)-FIND(":",G6)-1)),"") | J6: =IF(AND(I6="",H6=""),G6,H6&": "&I6) -> {#PHASEINDEX}: 不可接受的相位{#PHASEINDEX}输入电压(超出范围{$UPS.INPUT_VOLT.MIN.WARN}-{$UPS.INPUT_VOLT.MAX.WARN}伏{$TIME.PERIOD}) | K6: =IFERROR(IF(OR(MID(F6,FIND(":",F6)-1,1)="""",MID(F6,FIND(":",F6)-1,1)="}",MID(F6,FIND(":",F6)-1,1)=")",MID(F6,FIND(":",F6)-1,1)="]"),"",RIGHT(F6,LEN(F6)-FIND(":",F6)-1)),"")
A7: 25 | B7: (310/3) | C7: (11/11) | D7: APC Smart-UPS 3000 XLM by SNMP | E7: 18674 | F7: {#PHASEINDEX}: Unacceptable phase {#PHASEINDEX} output voltage (out of range {$UPS.INPUT_VOLT.MIN.WARN}-{$UPS.INPUT_VOLT.MAX.WARN}V for {$TIME.PERIOD}) | G7: {#PHASEINDEX}: 不可接受的阶段{#PHASEINDEX}输出电压(超出范围{$UPS.INPUT_VOLT.MIN.WARN}-{$UPS.INPUT_VOLT.MAX.WARN}伏{$TIME.PERIOD}) | H7: =IFERROR(IF(OR(MID(G7,FIND(":",G7)-1,1)="""",MID(G7,FIND(":",G7)-1,1)="}",MID(G7,FIND(":",G7)-1,1)=")",MID(G7,FIND(":",G7)-1,1)="]"),"",LEFT(F7,FIND(":",F7)-1)),"") | I7: =IFERROR(IF(OR(MID(G7,FIND(":",G7)-1,1)="""",MID(G7,FIND(":",G7)-1,1)="}",MID(G7,FIND(":",G7)-1,1)=")",MID(G7,FIND(":",G7)-1,1)="]"),"",RIGHT(G7,LEN(G7)-FIND(":",G7)-1)),"") | J7: =IF(AND(I7="",H7=""),G7,H7&": "&I7) -> {#PHASEINDEX}: 不可接受的阶段{#PHASEINDEX}输出电压(超出范围{$UPS.INPUT_VOLT.MIN.WARN}-{$UPS.INPUT_VOLT.MAX.WARN}伏{$TIME.PERIOD}) | K7: =IFERROR(IF(OR(MID(F7,FIND(":",F7)-1,1)="""",MID(F7,FIND(":",F7)-1,1)="}",MID(F7,FIND(":",F7)-1,1)=")",MID(F7,FIND(":",F7)-1,1)="]"),"",RIGHT(F7,LEN(F7)-FIND(":",F7)-1)),"")
A8: 28 | B8: (310/4) | C8: (11/3) | D8: APC Smart-UPS RT 1000 RM XL by SNMP | E8: 18699 | F8: {#BATTERY_PACK}.{#CARTRIDGE_INDEX}: Battery has high temperature (over {$BATTERY.TEMP.MAX.WARN}℃ for {$TIME.PERIOD}) | G8: {#BATTERY_PACK}.{#CARTRIDGE_INDEX}: 电池温度太高(超过{$BATTERY.TEMP.MAX.WARN}℃持续{$TIME.PERIOD}) | H8: =IFERROR(IF(OR(MID(G8,FIND(":",G8)-1,1)="""",MID(G8,FIND(":",G8)-1,1)="}",MID(G8,FIND(":",G8)-1,1)=")",MID(G8,FIND(":",G8)-1,1)="]"),"",LEFT(F8,FIND(":",F8)-1)),"") | I8: =IFERROR(IF(OR(MID(G8,FIND(":",G8)-1,1)="""",MID(G8,FIND(":",G8)-1,1)="}",MID(G8,FIND(":",G8)-1,1)=")",MID(G8,FIND(":",G8)-1,1)="]"),"",RIGHT(G8,LEN(G8)-FIND(":",G8)-1)),"") | J8: =IF(AND(I8="",H8=""),G8,H8&": "&I8) -> {#BATTERY_PACK}.{#CARTRIDGE_INDEX}: 电池温度太高(超过{$BATTERY.TEMP.MAX.WARN}℃持续{$TIME.PERIOD}) | K8: =IFERROR(IF(OR(MID(F8,FIND(":",F8)-1,1)="""",MID(F8,FIND(":",F8)-1,1)="}",MID(F8,FIND(":",F8)-1,1)=")",MID(F8,FIND(":",F8)-1,1)="]"),"",RIGHT(F8,LEN(F8)-FIND(":",F8)-1)),"")
A9: 35 | B9: (310/4) | C9: (11/10) | D9: APC Smart-UPS RT 1000 RM XL by SNMP | E9: 18706 | F9: {#PHASEINDEX}: Unacceptable phase {#PHASEINDEX} input voltage (out of range {$UPS.INPUT_VOLT.MIN.WARN}-{$UPS.INPUT_VOLT.MAX.WARN}V for {$TIME.PERIOD}) | G9: {#PHASEINDEX}: 不可接受的相位{#PHASEINDEX}输入电压(超出范围{$UPS.INPUT_VOLT.MIN.WARN}-{$UPS.INPUT_VOLT.MAX.WARN}伏{$TIME.PERIOD}) | H9: =IFERROR(IF(OR(MID(G9,FIND(":",G9)-1,1)="""",MID(G9,FIND(":",G9)-1,1)="}",MID(G9,FIND(":",G9)-1,1)=")",MID(G9,FIND(":",G9)-1,1)="]"),"",LEFT(F9,FIND(":",F9)-1)),"") | I9: =IFERROR(IF(OR(MID(G9,FIND(":",G9)-1,1)="""",MID(G9,FIND(":",G9)-1,1)="}",MID(G9,FIND(":",G9)-1,1)=")",MID(G9,FIND(":",G9)-1,1)="]"),"",RIGHT(G9,LEN(G9)-FIND(":",G9)-1)),"") | J9: =IF(AND(I9="",H9=""),G9,H9&": "&I9) -> {#PHASEINDEX}: 不可接受的相位{#PHASEINDEX}输入电压(超出范围{$UPS.INPUT_VOLT.MIN.WARN}-{$UPS.INPUT_VOLT.MAX.WARN}伏{$TIME.PERIOD}) | K9: =IFERROR(IF(OR(MID(F9,FIND(":",F9)-1,1)="""",MID(F9,FIND(":",F9)-1,1)="}",MID(F9,FIND(":",F9)-1,1)=")",MID(F9,FIND(":",F9)-1,1)="]"),"",RIGHT(F9,LEN(F9)-FIND(":",F9)-1)),"")
A10: 36 | B10: (310/4) | C10: (11/11) | D10: APC Smart-UPS RT 1000 RM XL by SNMP | E10: 18707 | F10: {#PHASEINDEX}: Unacceptable phase {#PHASEINDEX} output voltage (out of range {$UPS.INPUT_VOLT.MIN.WARN}-{$UPS.INPUT_VOLT.MAX.WARN}V for {$TIME.PERIOD}) | G10: {#PHASEINDEX}: 不可接受的阶段{#PHASEINDEX}输出电压(超出范围{$UPS.INPUT_VOLT.MIN.WARN}-{$UPS.INPUT_VOLT.MAX.WARN}伏{$TIME.PERIOD}) | H10: =IFERROR(IF(OR(MID(G10,FIND(":",G10)-1,1)="""",MID(G10,FIND(":",G10)-1,1)="}",MID(G10,FIND(":",G10)-1,1)=")",MID(G10,FIND(":",G10)-1,1)="]"),"",LEFT(F10,FIND(":",F10)-1)),"") | I10: =IFERROR(IF(OR(MID(G10,FIND(":",G10)-1,1)="""",MID(G10,FIND(":",G10)-1,1)="}",MID(G10,FIND(":",G10)-1,1)=")",MID(G10,FIND(":",G10)-1,1)="]"),"",RIGHT(G10,LEN(G10)-FIND(":",G10)-1)),"") | J10: =IF(AND(I10="",H10=""),G10,H10&": "&I10) -> {#PHASEINDEX}: 不可接受的阶段{#PHASEINDEX}输出电压(超出范围{$UPS.INPUT_VOLT.MIN.WARN}-{$UPS.INPUT_VOLT.MAX.WARN}伏{$TIME.PERIOD}) | K10: =IFERROR(IF(OR(MID(F10,FIND(":",F10)-1,1)="""",MID(F10,FIND(":",F10)-1,1)="}",MID(F10,FIND(":",F10)-1,1)=")",MID(F10,FIND(":",F10)-1,1)="]"),"",RIGHT(F10,LEN(F10)-FIND(":",F10)-1)),"")
A11: 39 | B11: (310/5) | C11: (11/3) | D11: APC Smart-UPS RT 1000 XL by SNMP | E11: 18732 | F11: {#BATTERY_PACK}.{#CARTRIDGE_INDEX}: Battery has high temperature (over {$BATTERY.TEMP.MAX.WARN}℃ for {$TIME.PERIOD}) | G11: {#BATTERY_PACK}.{#CARTRIDGE_INDEX}: 电池温度太高(超过{$BATTERY.TEMP.MAX.WARN}℃持续{$TIME.PERIOD}) | H11: =IFERROR(IF(OR(MID(G11,FIND(":",G11)-1,1)="""",MID(G11,FIND(":",G11)-1,1)="}",MID(G11,FIND(":",G11)-1,1)=")",MID(G11,FIND(":",G11)-1,1)="]"),"",LEFT(F11,FIND(":",F11)-1)),"") | I11: =IFERROR(IF(OR(MID(G11,FIND(":",G11)-1,1)="""",MID(G11,FIND(":",G11)-1,1)="}",MID(G11,FIND(":",G11)-1,1)=")",MID(G11,FIND(":",G11)-1,1)="]"),"",RIGHT(G11,LEN(G11)-FIND(":",G11)-1)),"") | J11: =IF(AND(I11="",H11=""),G11,H11&": "&I11) -> {#BATTERY_PACK}.{#CARTRIDGE_INDEX}: 电池温度太高(超过{$BATTERY.TEMP.MAX.WARN}℃持续{$TIME.PERIOD}) | K11: =IFERROR(IF(OR(MID(F11,FIND(":",F11)-1,1)="""",MID(F11,FIND(":",F11)-1,1)="}",MID(F11,FIND(":",F11)-1,1)=")",MID(F11,FIND(":",F11)-1,1)="]"),"",RIGHT(F11,LEN(F11)-FIND(":",F11)-1)),"")
A12: 46 | B12: (310/5) | C12: (11/10) | D12: APC Smart-UPS RT 1000 XL by SNMP | E12: 18739 | F12: {#PHASEINDEX}: Unacceptable phase {#PHASEINDEX} input voltage (out of range {$UPS.INPUT_VOLT.MIN.WARN}-{$UPS.INPUT_VOLT.MAX.WARN}V for {$TIME.PERIOD}) | G12: {#PHASEINDEX}: 不可接受的相位{#PHASEINDEX}输入电压(超出范围{$UPS.INPUT_VOLT.MIN.WARN}-{$UPS.INPUT_VOLT.MAX.WARN}伏{$TIME.PERIOD}) | H12: =IFERROR(IF(OR(MID(G12,FIND(":",G12)-1,1)="""",MID(G12,FIND(":",G12)-1,1)="}",MID(G12,FIND(":",G12)-1,1)=")",MID(G12,FIND(":",G12)-1,1)="]"),"",LEFT(F12,FIND(":",F12)-1)),"") | I12: =IFERROR(IF(OR(MID(G12,FIND(":",G12)-1,1)="""",MID(G12,FIND(":",G12)-1,1)="}",MID(G12,FIND(":",G12)-1,1)=")",MID(G12,FIND(":",G12)-1,1)="]"),"",RIGHT(G12,LEN(G12)-FIND(":",G12)-1)),"") | J12: =IF(AND(I12="",H12=""),G12,H12&": "&I12) -> {#PHASEINDEX}: 不可接受的相位{#PHASEINDEX}输入电压(超出范围{$UPS.INPUT_VOLT.MIN.WARN}-{$UPS.INPUT_VOLT.MAX.WARN}伏{$TIME.PERIOD}) | K12: =IFERROR(IF(OR(MID(F12,FIND(":",F12)-1,1)="""",MID(F12,FIND(":",F12)-1,1)="}",MID(F12,FIND(":",F12)-1,1)=")",MID(F12,FIND(":",F12)-1,1)="]"),"",RIGHT(F12,LEN(F12)-FIND(":",F12)-1)),"")
A13: 47 | B13: (310/5) | C13: (11/11) | D13: APC Smart-UPS RT 1000 XL by SNMP | E13: 18740 | F13: {#PHASEINDEX}: Unacceptable phase {#PHASEINDEX} output voltage (out of range {$UPS.INPUT_VOLT.MIN.WARN}-{$UPS.INPUT_VOLT.MAX.WARN}V for {$TIME.PERIOD}) | G13: {#PHASEINDEX}: 不可接受的阶段{#PHASEINDEX}输出电压(超出范围{$UPS.INPUT_VOLT.MIN.WARN}-{$UPS.INPUT_VOLT.MAX.WARN}伏{$TIME.PERIOD}) | H13: =IFERROR(IF(OR(MID(G13,FIND(":",G13)-1,1)="""",MID(G13,FIND(":",G13)-1,1)="}",MID(G13,FIND(":",G13)-1,1)=")",MID(G13,FIND(":",G13)-1,1)="]"),"",LEFT(F13,FIND(":",F13)-1)),"") | I13: =IFERROR(IF(OR(MID(G13,FIND(":",G13)-1,1)="""",MID(G13,FIND(":",G13)-1,1)="}",MID(G13,FIND(":",G13)-1,1)=")",MID(G13,FIND(":",G13)-1,1)="]"),"",RIGHT(G13,LEN(G13)-FIND(":",G13)-1)),"") | J13: =IF(AND(I13="",H13=""),G13,H13&": "&I13) -> {#PHASEINDEX}: 不可接受的阶段{#PHASEINDEX}输出电压(超出范围{$UPS.INPUT_VOLT.MIN.WARN}-{$UPS.INPUT_VOLT.MAX.WARN}伏{$TIME.PERIOD}) | K13: =IFERROR(IF(OR(MID(F13,FIND(":",F13)-1,1)="""",MID(F13,FIND(":",F13)-1,1)="}",MID(F13,FIND(":",F13)-1,1)=")",MID(F13,FIND(":",F13)-1,1)="]"),"",RIGHT(F13,LEN(F13)-FIND(":",F13)-1)),"")
... A1631: 3138 | B1631: (310/255) | C1631: (2/1) | D1631: Zookeeper by HTTP | E1631: 17528 | F1631: Zookeeper: Too many pending syncs (over {$ZOOKEEPER.PENDING_SYNCS.MAX.WARN}% for 5 min) | G1631: Zookeeper: 挂起的同步太多(超过{$ZOOKEEPER.PENDING_SYNCS.MAX.WARN}%达5分钟) | H1631: =IFERROR(IF(OR(MID(G1631,FIND(":",G1631)-1,1)="""",MID(G1631,FIND(":",G1631)-1,1)="}",MID(G1631,FIND(":",G1631)-1,1)=")",MID(G1631,FIND(":",G1631)-1,1)="]"),"",LEFT(F1631,FIND(":",F1631)-1)),"") -> Zookeeper | I1631: =IFERROR(IF(OR(MID(G1631,FIND(":",G1631)-1,1)="""",MID(G1631,FIND(":",G1631)-1,1)="}",MID(G1631,FIND(":",G1631)-1,1)=")",MID(G1631,FIND(":",G1631)-1,1)="]"),"",RIGHT(G1631,LEN(G1631)-FIND(":",G1631)-1)),"") -> 挂起的同步太多(超过{$ZOOKEEPER.PENDING_SYNCS.MAX.WARN}%达5分钟) | J1631: =IF(AND(I1631="",H1631=""),G1631,H1631&": "&I1631) -> Zookeeper: 挂起的同步太多(超过{$ZOOKEEPER.PENDING_SYNCS.MAX.WARN}%达5分钟) | K1631: =IFERROR(IF(OR(MID(F1631,FIND(":",F1631)-1,1)="""",MID(F1631,FIND(":",F1631)-1,1)="}",MID(F1631,FIND(":",F1631)-1,1)=")",MID(F1631,FIND(":",F1631)-1,1)="]"),"",RIGHT(F1631,LEN(F1631)-FIND(":",F1631)-1)),"") -> Too many pending syncs (over {$ZOOKEEPER.PENDING_SYNCS.MAX.WARN}% for 5 min)
